Workbook

Sheet Executive Summary
A1: Personal Injury Settlement & Bottleneck Analytics
A2: Synthetic data | As of 2026-10-13 | Summary values are live formulas over the CaseData tab
A4: KPI | B4: Value | C4: Definition
A5: Total cases | B5: =COUNTA(CaseData!$A$2:$A$201) -> 200 | C5: All intakes in dataset
A6: Closed cases | B6: =COUNTIF(CaseData!$F$2:$F$201,"Closed") -> 166 | C6: Closing statement signed
A7: Open cases | B7: =COUNTIF(CaseData!$F$2:$F$201,"Open") -> 34 | C7: No closing statement yet
A8: ACTIVE stagnation alerts | B8: =COUNTIF(CaseData!$AI$2:$AI$201,"Yes") -> 5 | C8: Open cases waiting > 45 days on records/bills or adjuster's first offer
A9: Historical stagnation rate | B9: =COUNTIF(CaseData!$AH$2:$AH$201,"Yes")/COUNTA(CaseData!$A$2:$A$201) -> 0.44 | C9: Cases that ever exceeded 45 days waiting on records or first offer
A10: Avg cycle, intake to closing (days) | B10: =AVERAGE(CaseData!$AA$2:$AA$201) -> 322.24699 | C10: Closed cases only
A11: Median cycle (days) | B11: =MEDIAN(CaseData!$AA$2:$AA$201) -> 301.5 | C11: Closed cases only
A12: Controllable share of cycle | B12: =SUM(CaseData!$AB$2:$AB$201)/SUM(CaseData!$AA$2:$AA$201) -> 0.16024527 | C12: Demand prep + settlement-to-closing (firm-owned work)
A13: External-wait share of cycle | B13: =SUMIFS(CaseData!$AC$2:$AC$201,CaseData!$F$2:$F$201,"Closed")/SUM(CaseData!$AA$2:$AA$201) -> 0.22847849 | C13: Records/bills wait + adjuster first-offer wait (third parties)
A14: Gross settlements accepted ($) | B14: =SUM(CaseData!$I$2:$I$201) -> 6846250 | C14: Includes accepted-not-yet-closed
A15: Attorney fees earned ($) | B15: =SUM(CaseData!$AF$2:$AF$201) -> 2341775 | C15: Settlement x fee % (33% pre-suit / 40% litigated)
A16: Original liens, closed cases ($) | B16: =SUMIFS(CaseData!$K$2:$K$201,CaseData!$F$2:$F$201,"Closed") -> 1325530.8 | C16: As asserted by lienholders
A17: Lien reduction savings ($) | B17: =SUM(CaseData!$AD$2:$AD$201) -> 491162.88 | C17: Original minus final negotiated liens
A18: Lien reduction (dollar-weighted) | B18: =B17/B16 -> 0.37054054 | C18: Savings / original liens
A20: Net_Attorney_Fee = settlement x fee %; case costs are treated as pass-through (not in dataset).

Sheet Phase Breakdown
A1: Where does the time go? (average days per phase, closed cases)
A3: Phase | B3: Owner | C3: Avg days | D3: % of cycle
A4: Treatment (intake to MMI) | B4: Client / medical | C4: =AVERAGEIFS(CaseData!$T$2:$T$201,CaseData!$F$2:$F$201,"Closed") -> 128.45181 | D4: =C4/SUM($C$4:$C$9) -> 0.3986129
A5: Records & bills wait | B5: EXTERNAL - providers | C5: =AVERAGEIFS(CaseData!$U$2:$U$201,CaseData!$F$2:$F$201,"Closed") -> 31.674699 | D5: =C5/SUM($C$4:$C$9) -> 0.098293235
A6: Demand preparation | B6: CONTROLLABLE - firm | C6: =AVERAGEIFS(CaseData!$V$2:$V$201,CaseData!$F$2:$F$201,"Closed") -> 16.927711 | D6: =C6/SUM($C$4:$C$9) -> 0.052530238
A7: Adjuster first-offer wait | B7: EXTERNAL - carrier | C7: =AVERAGEIFS(CaseData!$W$2:$W$201,CaseData!$F$2:$F$201,"Closed") -> 41.951807 | D7: =C7/SUM($C$4:$C$9) -> 0.13018526
A8: Negotiation | B8: Strategic / shared | C8: =AVERAGEIFS(CaseData!$X$2:$X$201,CaseData!$F$2:$F$201,"Closed") -> 68.53012 | D8: =C8/SUM($C$4:$C$9) -> 0.21266334
A9: Settlement to closing | B9: CONTROLLABLE - firm | C9: =AVERAGEIFS(CaseData!$Y$2:$Y$201,CaseData!$F$2:$F$201,"Closed") -> 34.710843 | D9: =C9/SUM($C$4:$C$9) -> 0.10771503
A10: Total | C10: =SUM(C4:C9) -> 322.24699 | D10: =SUM(D4:D9) -> 1

Sheet Case Manager
A1: Case manager scorecard (firm-controllable efficiency + lien results)
A3: Case manager | B3: Cases | C3: Avg demand prep (d) | D3: Avg settlement-to-closing (d) | E3: Avg controllable days | F3: Lien reduction % ($-weighted) | G3: Lien savings ($) | H3: Attorney fees ($)
A4: Alicia Reyes | B4: =COUNTIF(CaseData!$D$2:$D$201,A4) -> 42 | C4: =IFERROR(AVERAGEIFS(CaseData!$V$2:$V$201,CaseData!$D$2:$D$201,A4),"") -> 17.390244 | D4: =IFERROR(AVERAGEIFS(CaseData!$Y$2:$Y$201,CaseData!$D$2:$D$201,A4),"") -> 28.342857 | E4: =IFERROR(AVERAGEIFS(CaseData!$AB$2:$AB$201,CaseData!$D$2:$D$201,A4),"") -> 44.4 | F4: =IFERROR(SUMIFS(CaseData!$AD$2:$AD$201,CaseData!$D$2:$D$201,A4)/SUMIFS(CaseData!$K$2:$K$201,CaseData!$D$2:$D$201,A4,CaseData!$F$2:$F$201,"Closed"),"") -> 0.27806127 | G4: =SUMIFS(CaseData!$AD$2:$AD$201,CaseData!$D$2:$D$201,A4) -> 69526.73 | H4: =SUMIFS(CaseData!$AF$2:$AF$201,CaseData!$D$2:$D$201,A4) -> 486090
A5: Daniel Kowalski | B5: =COUNTIF(CaseData!$D$2:$D$201,A5) -> 35 | C5: =IFERROR(AVERAGEIFS(CaseData!$V$2:$V$201,CaseData!$D$2:$D$201,A5),"") -> 19.176471 | D5: =IFERROR(AVERAGEIFS(CaseData!$Y$2:$Y$201,CaseData!$D$2:$D$201,A5),"") -> 38.322581 | E5: =IFERROR(AVERAGEIFS(CaseData!$AB$2:$AB$201,CaseData!$D$2:$D$201,A5),"") -> 55.806452 | F5: =IFERROR(SUMIFS(CaseData!$AD$2:$AD$201,CaseData!$D$2:$D$201,A5)/SUMIFS(CaseData!$K$2:$K$201,CaseData!$D$2:$D$201,A5,CaseData!$F$2:$F$201,"Closed"),"") -> 0.46961766 | G5: =SUMIFS(CaseData!$AD$2:$AD$201,CaseData!$D$2:$D$201,A5) -> 112804.44 | H5: =SUMIFS(CaseData!$AF$2:$AF$201,CaseData!$D$2:$D$201,A5) -> 364177.5
A6: Jennifer Ortiz | B6: =COUNTIF(CaseData!$D$2:$D$201,A6) -> 46 | C6: =IFERROR(AVERAGEIFS(CaseData!$V$2:$V$201,CaseData!$D$2:$D$201,A6),"") -> 16.086957 | D6: =IFERROR(AVERAGEIFS(CaseData!$Y$2:$Y$201,CaseData!$D$2:$D$201,A6),"") -> 33.4 | E6: =IFERROR(AVERAGEIFS(CaseData!$AB$2:$AB$201,CaseData!$D$2:$D$201,A6),"") -> 49.485714 | F6: =IFERROR(SUMIFS(CaseData!$AD$2:$AD$201,CaseData!$D$2:$D$201,A6)/SUMIFS(CaseData!$K$2:$K$201,CaseData!$D$2:$D$201,A6,CaseData!$F$2:$F$201,"Closed"),"") -> 0.33358056 | G6: =SUMIFS(CaseData!$AD$2:$AD$201,CaseData!$D$2:$D$201,A6) -> 104329.8 | H6: =SUMIFS(CaseData!$AF$2:$AF$201,CaseData!$D$2:$D$201,A6) -> 551892.5
A7: Marcus Bell | B7: =COUNTIF(CaseData!$D$2:$D$201,A7) -> 34 | C7: =IFERROR(AVERAGEIFS(CaseData!$V$2:$V$201,CaseData!$D$2:$D$201,A7),"") -> 23.25 | D7: =IFERROR(AVERAGEIFS(CaseData!$Y$2:$Y$201,CaseData!$D$2:$D$201,A7),"") -> 45.068966 | E7: =IFERROR(AVERAGEIFS(CaseData!$AB$2:$AB$201,CaseData!$D$2:$D$201,A7),"") -> 69.068966 | F7: =IFERROR(SUMIFS(CaseData!$AD$2:$AD$201,CaseData!$D$2:$D$201,A7)/SUMIFS(CaseData!$K$2:$K$201,CaseData!$D$2:$D$201,A7,CaseData!$F$2:$F$201,"Closed"),"") -> 0.38966413 | G7: =SUMIFS(CaseData!$AD$2:$AD$201,CaseData!$D$2:$D$201,A7) -> 85234.48 | H7: =SUMIFS(CaseData!$AF$2:$AF$201,CaseData!$D$2:$D$201,A7) -> 448192.5
A8: Priya Nair | B8: =COUNTIF(CaseData!$D$2:$D$201,A8) -> 43 | C8: =IFERROR(AVERAGEIFS(CaseData!$V$2:$V$201,CaseData!$D$2:$D$201,A8),"") -> 11.857143 | D8: =IFERROR(AVERAGEIFS(CaseData!$Y$2:$Y$201,CaseData!$D$2:$D$201,A8),"") -> 30.722222 | E8: =IFERROR(AVERAGEIFS(CaseData!$AB$2:$AB$201,CaseData!$D$2:$D$201,A8),"") -> 43.138889 | F8: =IFERROR(SUMIFS(CaseData!$AD$2:$AD$201,CaseData!$D$2:$D$201,A8)/SUMIFS(CaseData!$K$2:$K$201,CaseData!$D$2:$D$201,A8,CaseData!$F$2:$F$201,"Closed"),"") -> 0.39259943 | G8: =SUMIFS(CaseData!$AD$2:$AD$201,CaseData!$D$2:$D$201,A8) -> 119267.43 | H8: =SUMIFS(CaseData!$AF$2:$AF$201,CaseData!$D$2:$D$201,A8) -> 491422.5

Sheet Carrier
A1: Carrier response time (external wait) - ILLUSTRATIVE synthetic data
A3: Insurance company | B3: Cases w/ first offer | C3: Avg days demand to offer | D3: % offers > 45 days | E3: Avg settlement ($)
A4: Allstate | B4: =COUNTIFS(CaseData!$E$2:$E$201,A4,CaseData!$W$2:$W$201,">=0") -> 45 | C4: =IFERROR(AVERAGEIFS(CaseData!$W$2:$W$201,CaseData!$E$2:$E$201,A4),"") -> 45.444444 | D4: =IFERROR(COUNTIFS(CaseData!$E$2:$E$201,A4,CaseData!$W$2:$W$201,">45")/B4,"") -> 0.37777778 | E4: =IFERROR(AVERAGEIFS(CaseData!$I$2:$I$201,CaseData!$E$2:$E$201,A4),"") -> 33871.795
A5: GEICO | B5: =COUNTIFS(CaseData!$E$2:$E$201,A5,CaseData!$W$2:$W$201,">=0") -> 29 | C5: =IFERROR(AVERAGEIFS(CaseData!$W$2:$W$201,CaseData!$E$2:$E$201,A5),"") -> 33 | D5: =IFERROR(COUNTIFS(CaseData!$E$2:$E$201,A5,CaseData!$W$2:$W$201,">45")/B5,"") -> 0.13793103 | E5: =IFERROR(AVERAGEIFS(CaseData!$I$2:$I$201,CaseData!$E$2:$E$201,A5),"") -> 38440
A6: Liberty Mutual | B6: =COUNTIFS(CaseData!$E$2:$E$201,A6,CaseData!$W$2:$W$201,">=0") -> 44 | C6: =IFERROR(AVERAGEIFS(CaseData!$W$2:$W$201,CaseData!$E$2:$E$201,A6),"") -> 46.863636 | D6: =IFERROR(COUNTIFS(CaseData!$E$2:$E$201,A6,CaseData!$W$2:$W$201,">45")/B6,"") -> 0.43181818 | E6: =IFERROR(AVERAGEIFS(CaseData!$I$2:$I$201,CaseData!$E$2:$E$201,A6),"") -> 42523.256
A7: Progressive | B7: =COUNTIFS(CaseData!$E$2:$E$201,A7,CaseData!$W$2:$W$201,">=0") -> 31 | C7: =IFERROR(AVERAGEIFS(CaseData!$W$2:$W$201,CaseData!$E$2:$E$201,A7),"") -> 36.322581 | D7: =IFERROR(COUNTIFS(CaseData!$E$2:$E$201,A7,CaseData!$W$2:$W$201,">45")/B7,"") -> 0.19354839 | E7: =IFERROR(AVERAGEIFS(CaseData!$I$2:$I$201,CaseData!$E$2:$E$201,A7),"") -> 52196.429
A8: State Farm | B8: =COUNTIFS(CaseData!$E$2:$E$201,A8,CaseData!$W$2:$W$201,">=0") -> 39 | C8: =IFERROR(AVERAGEIFS(CaseData!$W$2:$W$201,CaseData!$E$2:$E$201,A8),"") -> 42.461538 | D8: =IFERROR(COUNTIFS(CaseData!$E$2:$E$201,A8,CaseData!$W$2:$W$201,">45")/B8,"") -> 0.35897436 | E8: =IFERROR(AVERAGEIFS(CaseData!$I$2:$I$201,CaseData!$E$2:$E$201,A8),"") -> 34439.189

Sheet Injury Type
A1: Injury type economics
A3: Injury type | B3: Cases | C3: Avg billed ($) | D3: Avg settlement ($) | E3: Avg cycle (days) | F3: % litigated (40% fee)
A4: Motor Vehicle Accident | B4: =COUNTIF(CaseData!$C$2:$C$201,A4) -> 116 | C4: =IFERROR(AVERAGEIFS(CaseData!$H$2:$H$201,CaseData!$C$2:$C$201,A4),"") -> 29334.269 | D4: =IFERROR(AVERAGEIFS(CaseData!$I$2:$I$201,CaseData!$C$2:$C$201,A4),"") -> 34897.5 | E4: =IFERROR(AVERAGEIFS(CaseData!$AA$2:$AA$201,CaseData!$C$2:$C$201,A4),"") -> 322.55208 | F4: =COUNTIFS(CaseData!$C$2:$C$201,A4,CaseData!$J$2:$J$201,0.4)/B4 -> 0.18965517
A5: Slip & Fall | B5: =COUNTIF(CaseData!$C$2:$C$201,A5) -> 38 | C5: =IFERROR(AVERAGEIFS(CaseData!$H$2:$H$201,CaseData!$C$2:$C$201,A5),"") -> 35175.602 | D5: =IFERROR(AVERAGEIFS(CaseData!$I$2:$I$201,CaseData!$C$2:$C$201,A5),"") -> 62046.875 | E5: =IFERROR(AVERAGEIFS(CaseData!$AA$2:$AA$201,CaseData!$C$2:$C$201,A5),"") -> 334.48387 | F5: =COUNTIFS(CaseData!$C$2:$C$201,A5,CaseData!$J$2:$J$201,0.4)/B5 -> 0.34210526
A6: Pedestrian | B6: =COUNTIF(CaseData!$C$2:$C$201,A6) -> 28 | C6: =IFERROR(AVERAGEIFS(CaseData!$H$2:$H$201,CaseData!$C$2:$C$201,A6),"") -> 54242.901 | D6: =IFERROR(AVERAGEIFS(CaseData!$I$2:$I$201,CaseData!$C$2:$C$201,A6),"") -> 46647.727 | E6: =IFERROR(AVERAGEIFS(CaseData!$AA$2:$AA$201,CaseData!$C$2:$C$201,A6),"") -> 377.2381 | F6: =COUNTIFS(CaseData!$C$2:$C$201,A6,CaseData!$J$2:$J$201,0.4)/B6 -> 0.14285714
A7: Dog Bite | B7: =COUNTIF(CaseData!$C$2:$C$201,A7) -> 18 | C7: =IFERROR(AVERAGEIFS(CaseData!$H$2:$H$201,CaseData!$C$2:$C$201,A7),"") -> 9733.4417 | D7: =IFERROR(AVERAGEIFS(CaseData!$I$2:$I$201,CaseData!$C$2:$C$201,A7),"") -> 19152.778 | E7: =IFERROR(AVERAGEIFS(CaseData!$AA$2:$AA$201,CaseData!$C$2:$C$201,A7),"") -> 235.38889 | F7: =COUNTIFS(CaseData!$C$2:$C$201,A7,CaseData!$J$2:$J$201,0.4)/B7 -> 0.11111111

Sheet Active Alerts
A1: case_id | B1: client_name | C1: case_manager | D1: insurance_company | E1: current_stage | F1: stagnation_type | G1: days_without_progress
A2: PI-2025-093 | B2: Brian Lewis | C2: Jennifer Ortiz | D2: Liberty Mutual | E2: 4. Awaiting Adjuster Offer | F2: Adjuster Offer | G2: 133
A3: PI-2026-006 | B3: David Williams | C3: Marcus Bell | D3: Allstate | E3: 2. Awaiting Records/Bills | F3: Records/Bills | G3: 101
A4: PI-2025-084 | B4: Brittany Garcia | C4: Priya Nair | D4: Liberty Mutual | E4: 4. Awaiting Adjuster Offer | F4: Records + Adjuster | G4: 86
A5: PI-2025-069 | B5: Rachel Ramirez | C5: Jennifer Ortiz | D5: Liberty Mutual | E5: 4. Awaiting Adjuster Offer | F5: Adjuster Offer | G5: 57
A6: PI-2026-010 | B6: Anthony Jackson | C6: Marcus Bell | D6: Progressive | E6: 2. Awaiting Records/Bills | F6: Records/Bills | G6: 53
A8: Open cases with > 45 days waiting on records/bills or an adjuster's first offer, as of 2026-10-13.

Sheet CaseData
A1: case_id | B1: client_name | C1: injury_type | D1: case_manager | E1: insurance_company | F1: case_status | G1: current_stage | H1: total_medical_bills | I1: settlement_amount | J1: attorney_fee_pct | K1: original_liens_amount | L1: final_reduced_liens_amount | M1: intake_date | N1: treatment_completion_date | O1: medical_records_received_date | P1: demand_sent_date | Q1: first_offer_date | R1: settlement_accepted_date | S1: closing_statement_date | T1: treatment_days | U1: records_wait_days | V1: demand_prep_days | W1: offer_wait_days | X1: negotiation_days | Y1: closing_days | Z1: intake_to_demand_days | AA1: total_cycle_days | AB1: controllable_days | AC1: external_wait_days | AD1: lien_reduction_savings | AE1: lien_reduction_pct | AF1: net_attorney_fee | AG1: client_net_recovery_before_costs | AH1: stagnant_case_flag | AI1: active_stagnation_alert | AJ1: stagnation_type
A2: PI-2024-001 | B2: Linda Lewis | C2: Slip & Fall | D2: Marcus Bell | E2: State Farm | F2: Closed | G2: 7. Closed | H2: 19366.57 | I2: 32250 | J2: 0.4 | K2: 6178.05 | L2: 4808.49 | M2: 45358 | N2: 45466 | O2: 45532 | P2: 45554 | Q2: 45589 | R2: 45817 | S2: 45877 | T2: 108 | U2: 66 | V2: 22 | W2: 35 | X2: 228 | Y2: 60 | Z2: 196 | AA2: 519 | AB2: 82 | AC2: 101 | AD2: 1369.56 | AE2: 22.2 | AF2: 12900 | AG2: 14541.51 | AH2: Yes | AI2: No | AJ2: Records/Bills
A3: PI-2024-002 | B3: David Thomas | C3: Motor Vehicle Accident | D3: Alicia Reyes | E3: Progressive | F3: Closed | G3: 7. Closed | H3: 37848.99 | I3: 100000 | J3: 0.33 | K3: 6758.17 | L3: 3317.32 | M3: 45361 | N3: 45484 | O3: 45551 | P3: 45579 | Q3: 45615 | R3: 45657 | S3: 45697 | T3: 123 | U3: 67 | V3: 28 | W3: 36 | X3: 42 | Y3: 40 | Z3: 218 | AA3: 336 | AB3: 68 | AC3: 103 | AD3: 3440.85 | AE3: 50.9 | AF3: 33000 | AG3: 63682.68 | AH3: Yes | AI3: No | AJ3: Records/Bills
A4: PI-2024-003 | B4: Ashley Clark | C4: Motor Vehicle Accident | D4: Daniel Kowalski | E4: Progressive | F4: Closed | G4: 7. Closed | H4: 6224.91 | I4: 9000 | J4: 0.33 | K4: 2301.48 | L4: 1584.3 | M4: 45362 | N4: 45419 | O4: 45440 | P4: 45452 | Q4: 45490 | R4: 45516 | S4: 45539 | T4: 57 | U4: 21 | V4: 12 | W4: 38 | X4: 26 | Y4: 23 | Z4: 90 | AA4: 177 | AB4: 35 | AC4: 59 | AD4: 717.18 | AE4: 31.2 | AF4: 2970 | AG4: 4445.7 | AH4: No | AI4: No
A5: PI-2024-004 | B5: Keisha Lewis | C5: Pedestrian | D5: Jennifer Ortiz | E5: Allstate | F5: Closed | G5: 7. Closed | H5: 56088.19 | I5: 149500 | J5: 0.33 | K5: 14872.22 | L5: 14446.09 | M5: 45363 | N5: 45755 | O5: 45778 | P5: 45795 | Q5: 45827 | R5: 45835 | S5: 45865 | T5: 392 | U5: 23 | V5: 17 | W5: 32 | X5: 8 | Y5: 30 | Z5: 432 | AA5: 502 | AB5: 47 | AC5: 55 | AD5: 426.13 | AE5: 2.9 | AF5: 49335 | AG5: 85718.91 | AH5: No | AI5: No
A6: PI-2024-005 | B6: Lauren Sanchez | C6: Motor Vehicle Accident | D6: Daniel Kowalski | E6: Allstate | F6: Closed | G6: 7. Closed | H6: 17513.15 | I6: 30500 | J6: 0.33 | K6: 4425.38 | L6: 3075.74 | M6: 45364 | N6: 45449 | O6: 45474 | P6: 45483 | Q6: 45534 | R6: 45557 | S6: 45581 | T6: 85 | U6: 25 | V6: 9 | W6: 51 | X6: 23 | Y6: 24 | Z6: 119 | AA6: 217 | AB6: 33 | AC6: 76 | AD6: 1349.64 | AE6: 30.5 | AF6: 10065 | AG6: 17359.26 | AH6: Yes | AI6: No | AJ6: Adjuster Offer
A7: PI-2024-006 | B7: Sofia White | C7: Motor Vehicle Accident | D7: Daniel Kowalski | E7: Allstate | F7: Closed | G7: 7. Closed | H7: 48508.51 | I7: 72750 | J7: 0.33 | K7: 12528.41 | L7: 6851.49 | M7: 45379 | N7: 45623 | O7: 45644 | P7: 45663 | Q7: 45687 | R7: 45700 | S7: 45758 | T7: 244 | U7: 21 | V7: 19 | W7: 24 | X7: 13 | Y7: 58 | Z7: 284 | AA7: 379 | AB7: 77 | AC7: 45 | AD7: 5676.92 | AE7: 45.3 | AF7: 24007.5 | AG7: 41891.01 | AH7: No | AI7: No
A8: PI-2024-007 | B8: Anthony Thomas | C8: Slip & Fall | D8: Alicia Reyes | E8: Allstate | F8: Closed | G8: 7. Closed | H8: 46266.55 | I8: 47500 | J8: 0.4 | K8: 14250 | L8: 13615.06 | M8: 45380 | N8: 45487 | O8: 45515 | P8: 45530 | Q8: 45587 | R8: 45913 | S8: 45933 | T8: 107 | U8: 28 | V8: 15 | W8: 57 | X8: 326 | Y8: 20 | Z8: 150 | AA8: 553 | AB8: 35 | AC8: 85 | AD8: 634.94 | AE8: 4.5 | AF8: 19000 | AG8: 14884.94 | AH8: Yes | AI8: No | AJ8: Adjuster Offer
A9: PI-2024-008 | B9: Sofia Garcia | C9: Motor Vehicle Accident | D9: Marcus Bell | E9: State Farm | F9: Closed | G9: 7. Closed | H9: 7375.88 | I9: 11500 | J9: 0.33 | K9: 3450 | L9: 3137.74 | M9: 45383 | N9: 45492 | O9: 45518 | P9: 45538 | Q9: 45580 | R9: 45606 | S9: 45658 | T9: 109 | U9: 26 | V9: 20 | W9: 42 | X9: 26 | Y9: 52 | Z9: 155 | AA9: 275 | AB9: 72 | AC9: 68 | AD9: 312.26 | AE9: 9.1 | AF9: 3795 | AG9: 4567.26 | AH9: No | AI9: No
A10: PI-2024-009 | B10: Robert Lopez | C10: Dog Bite | D10: Daniel Kowalski | E10: Liberty Mutual | F10: Closed | G10: 7. Closed | H10: 14128.63 | I10: 32750 | J10: 0.4 | K10: 4697.03 | L10: 3151.65 | M10: 45385 | N10: 45409 | O10: 45530 | P10: 45563 | Q10: 45597 | R10: 45813 | S10: 45846 | T10: 24 | U10: 121 | V10: 33 | W10: 34 | X10: 216 | Y10: 33 | Z10: 178 | AA10: 461 | AB10: 66 | AC10: 155 | AD10: 1545.38 | AE10: 32.9 | AF10: 13100 | AG10: 16498.35 | AH10: Yes | AI10: No | AJ10: Records/Bills
A11: PI-2024-010 | B11: Patricia Harris | C11: Motor Vehicle Accident | D11: Alicia Reyes | E11: Liberty Mutual | F11: Closed | G11: 7. Closed | H11: 18335.89 | I11: 30500 | J11: 0.33 | K11: 3599.73 | L11: 3383.44 | M11: 45394 | N11: 45493 | O11: 45553 | P11: 45562 | Q11: 45622 | R11: 45700 | S11: 45717 | T11: 99 | U11: 60 | V11: 9 | W11: 60 | X11: 78 | Y11: 17 | Z11: 168 | AA11: 323 | AB11: 26 | AC11: 120 | AD11: 216.29 | AE11: 6 | AF11: 10065 | AG11: 17051.56 | AH11: Yes | AI11: No | AJ11: Records + Adjuster
A12: PI-2024-011 | B12: Anthony Reyes | C12: Pedestrian | D12: Priya Nair | E12: Progressive | F12: Closed | G12: 7. Closed | H12: 28562.46 | I12: 25000 | J12: 0.33 | K12: 5799.38 | L12: 4327.76 | M12: 45395 | N12: 45654 | O12: 45672 | P12: 45691 | Q12: 45710 | R12: 45761 | S12: 45783 | T12: 259 | U12: 18 | V12: 19 | W12: 19 | X12: 51 | Y12: 22 | Z12: 296 | AA12: 388 | AB12: 41 | AC12: 37 | AD12: 1471.62 | AE12: 25.4 | AF12: 8250 | AG12: 12422.24 | AH12: No | AI12: No
A13: PI-2024-012 | B13: Sofia Taylor | C13: Motor Vehicle Accident | D13: Priya Nair | E13: Liberty Mutual | F13: Closed | G13: 7. Closed | H13: 34681.47 | I13: 15000 | J13: 0.33 | K13: 12000 | L13: 5250 | M13: 45397 | N13: 45525 | O13: 45613 | P13: 45619 | Q13: 45660 | R13: 45713 | S13: 45740 | T13: 128 | U13: 88 | V13: 6 | W13: 41 | X13: 53 | Y13: 27 | Z13: 222 | AA13: 343 | AB13: 33 | AC13: 129 | AD13: 6750 | AE13: 56.2 | AF13: 4950 | AG13: 4800 | AH13: Yes | AI13: No | AJ13: Records/Bills
A14: PI-2024-013 | B14: Jose Lewis | C14: Motor Vehicle Accident | D14: Alicia Reyes | E14: GEICO | F14: Closed | G14: 7. Closed | H14: 24581.47 | I14: 15000 | J14: 0.33 | K14: 12000 | L14: 5250 | M14: 45399 | N14: 45467 | O14: 45492 | P14: 45521 | Q14: 45562 | R14: 45581 | S14: 45610 | T14: 68 | U14: 25 | V14: 29 | W14: 41 | X14: 19 | Y14: 29 | Z14: 122 | AA14: 211 | AB14: 58 | AC14: 66 | AD14: 6750 | AE14: 56.2 | AF14: 4950 | AG14: 4800 | AH14: No | AI14: No
A15: PI-2024-014 | B15: Jose Perez | C15: Pedestrian | D15: Jennifer Ortiz | E15: Progressive | F15: Closed | G15: 7. Closed | H15: 32949.79 | I15: 70250 | J15: 0.33 | K15: 6045.55 | L15: 5671.67 | M15: 45401 | N15: 45701 | O15: 45808 | P15: 45824 | Q15: 45851 | R15: 45892 | S15: 45922 | T15: 300 | U15: 107 | V15: 16 | W15: 27 | X15: 41 | Y15: 30 | Z15: 423 | AA15: 521 | AB15: 46 | AC15: 134 | AD15: 373.88 | AE15: 6.2 | AF15: 23182.5 | AG15: 41395.83 | AH15: Yes | AI15: No | AJ15: Records/Bills
A16: PI-2024-015 | B16: Eric Moore | C16: Motor Vehicle Accident | D16: Alicia Reyes | E16: Progressive | F16: Closed | G16: 7. Closed | H16: 43216.01 | I16: 50000 | J16: 0.33 | K16: 18212.34 | L16: 12769.89 | M16: 45405 | N16: 45573 | O16: 45617 | P16: 45634 | Q16: 45653 | R16: 45672 | S16: 45706 | T16: 168 | U16: 44 | V16: 17 | W16: 19 | X16: 19 | Y16: 34 | Z16: 229 | AA16: 301 | AB16: 51 | AC16: 63 | AD16: 5442.45 | AE16: 29.9 | AF16: 16500 | AG16: 20730.11 | AH16: No | AI16: No
A17: PI-2024-016 | B17: Monica Torres | C17: Slip & Fall | D17: Alicia Reyes | E17: Allstate | F17: Closed | G17: 7. Closed | H17: 38205.42 | I17: 71000 | J17: 0.33 | K17: 15770.49 | L17: 10602.83 | M17: 45405 | N17: 45613 | O17: 45634 | P17: 45651 | Q17: 45737 | R17: 45747 | S17: 45783 | T17: 208 | U17: 21 | V17: 17 | W17: 86 | X17: 10 | Y17: 36 | Z17: 246 | AA17: 378 | AB17: 53 | AC17: 107 | AD17: 5167.66 | AE17: 32.8 | AF17: 23430 | AG17: 36967.17 | AH17: Yes | AI17: No | AJ17: Adjuster Offer
A18: PI-2024-017 | B18: Andre Walker | C18: Motor Vehicle Accident | D18: Jennifer Ortiz | E18: State Farm | F18: Closed | G18: 7. Closed | H18: 37463.94 | I18: 50000 | J18: 0.33 | K18: 13078.02 | L18: 8010.94 | M18: 45408 | N18: 45506 | O18: 45572 | P18: 45614 | Q18: 45661 | R18: 45727 | S18: 45751 | T18: 98 | U18: 66 | V18: 42 | W18: 47 | X18: 66 | Y18: 24 | Z18: 206 | AA18: 343 | AB18: 66 | AC18: 113 | AD18: 5067.08 | AE18: 38.7 | AF18: 16500 | AG18: 25489.06 | AH18: Yes | AI18: No | AJ18: Records + Adjuster
A19: PI-2024-018 | B19: Angela Perez | C19: Slip & Fall | D19: Alicia Reyes | E19: Liberty Mutual | F19: Closed | G19: 7. Closed | H19: 53743.48 | I19: 100000 | J19: 0.33 | K19: 11540.78 | L19: 6480.88 | M19: 45409 | N19: 45502 | O19: 45518 | P19: 45527 | Q19: 45565 | R19: 45596 | S19: 45630 | T19: 93 | U19: 16 | V19: 9 | W19: 38 | X19: 31 | Y19: 34 | Z19: 118 | AA19: 221 | AB19: 43 | AC19: 54 | AD19: 5059.9 | AE19: 43.8 | AF19: 33000 | AG19: 60519.12 | AH19: No | AI19: No
A20: PI-2024-019 | B20: Kevin Gonzalez | C20: Slip & Fall | D20: Jennifer Ortiz | E20: Liberty Mutual | F20: Closed | G20: 7. Closed | H20: 3228.94 | I20: 4000 | J20: 0.33 | K20: 581.39 | L20: 448.4 | M20: 45417 | N20: 45557 | O20: 45568 | P20: 45581 | Q20: 45619 | R20: 45703 | S20: 45721 | T20: 140 | U20: 11 | V20: 13 | W20: 38 | X20: 84 | Y20: 18 | Z20: 164 | AA20: 304 | AB20: 31 | AC20: 49 | AD20: 132.99 | AE20: 22.9 | AF20: 1320 | AG20: 2231.6 | AH20: No | AI20: No
A21: PI-2024-020 | B21: James Clark | C21: Dog Bite | D21: Priya Nair | E21: State Farm | F21: Closed | G21: 7. Closed | H21: 10155.15 | I21: 16000 | J21: 0.33 | K21: 1753.27 | L21: 757.12 | M21: 45427 | N21: 45496 | O21: 45539 | P21: 45543 | Q21: 45565 | R21: 45587 | S21: 45610 | T21: 69 | U21: 43 | V21: 4 | W21: 22 | X21: 22 | Y21: 23 | Z21: 116 | AA21: 183 | AB21: 27 | AC21: 65 | AD21: 996.15 | AE21: 56.8 | AF21: 5280 | AG21: 9962.88 | AH21: No | AI21: No
A22: PI-2024-021 | B22: Anthony Johnson | C22: Slip & Fall | D22: Marcus Bell | E22: Liberty Mutual | F22: Closed | G22: 7. Closed | H22: 15837.74 | I22: 23750 | J22: 0.33 | K22: 7153.3 | L22: 6278.04 | M22: 45429 | N22: 45691 | O22: 45702 | P22: 45713 | Q22: 45749 | R22: 45812 | S22: 45861 | T22: 262 | U22: 11 | V22: 11 | W22: 36 | X22: 63 | Y22: 49 | Z22: 284 | AA22: 432 | AB22: 60 | AC22: 47 | AD22: 875.26 | AE22: 12.2 | AF22: 7837.5 | AG22: 9634.46 | AH22: No | AI22: No
A23: PI-2024-022 | B23: Keisha Hernandez | C23: Motor Vehicle Accident | D23: Daniel Kowalski | E23: GEICO | F23: Closed | G23: 7. Closed | H23: 6942.58 | I23: 9250 | J23: 0.33 | K23: 2376.16 | L23: 2246.19 | M23: 45429 | N23: 45695 | O23: 45718 | P23: 45729 | Q23: 45759 | R23: 45799 | S23: 45837 | T23: 266 | U23: 23 | V23: 11 | W23: 30 | X23: 40 | Y23: 38 | Z23: 300 | AA23: 408 | AB23: 49 | AC23: 53 | AD23: 129.97 | AE23: 5.5 | AF23: 3052.5 | AG23: 3951.31 | AH23: No | AI23: No
A24: PI-2024-023 | B24: Sofia Lewis | C24: Motor Vehicle Accident | D24: Jennifer Ortiz | E24: Allstate | F24: Closed | G24: 7. Closed | H24: 40247.36 | I24: 50000 | J24: 0.33 | K24: 12841.84 | L24: 9401.38 | M24: 45430 | N24: 45515 | O24: 45598 | P24: 45609 | Q24: 45650 | R24: 45662 | S24: 45700 | T24: 85 | U24: 83 | V24: 11 | W24: 41 | X24: 12 | Y24: 38 | Z24: 179 | AA24: 270 | AB24: 49 | AC24: 124 | AD24: 3440.46 | AE24: 26.8 | AF24: 16500 | AG24: 24098.62 | AH24: Yes | AI24: No | AJ24: Records/Bills
A25: PI-2024-024 | B25: Luis Perez | C25: Dog Bite | D25: Daniel Kowalski | E25: Liberty Mutual | F25: Closed | G25: 7. Closed | H25: 7086 | I25: 20250 | J25: 0.33 | K25: 2441.82 | L25: 1435.23 | M25: 45431 | N25: 45490 | O25: 45507 | P25: 45513 | Q25: 45579 | R25: 45588 | S25: 45629 | T25: 59 | U25: 17 | V25: 6 | W25: 66 | X25: 9 | Y25: 41 | Z25: 82 | AA25: 198 | AB25: 47 | AC25: 83 | AD25: 1006.59 | AE25: 41.2 | AF25: 6682.5 | AG25: 12132.27 | AH25: Yes | AI25: No | AJ25: Adjuster Offer
A26: PI-2024-025 | B26: Carlos Sanchez | C26: Motor Vehicle Accident | D26: Priya Nair | E26: GEICO | F26: Closed | G26: 7. Closed | H26: 19227.46 | I26: 25000 | J26: 0.33 | K26: 2046.19 | L26: 1633.28 | M26: 45436 | N26: 45796 | O26: 45880 | P26: 45884 | Q26: 45922 | R26: 45940 | S26: 45965 | T26: 360 | U26: 84 | V26: 4 | W26: 38 | X26: 18 | Y26: 25 | Z26: 448 | AA26: 529 | AB26: 29 | AC26: 122 | AD26: 412.91 | AE26: 20.2 | AF26: 8250 | AG26: 15116.72 | AH26: Yes | AI26: No | AJ26: Records/Bills
A27: PI-2024-026 | B27: Jose Walker | C27: Motor Vehicle Accident | D27: Alicia Reyes | E27: Progressive | F27: Closed | G27: 7. Closed | H27: 11138.84 | I27: 34000 | J27: 0.33 | K27: 8020.12 | L27: 7775.81 | M27: 45436 | N27: 45549 | O27: 45565 | P27: 45574 | Q27: 45614 | R27: 45628 | S27: 45645 | T27: 113 | U27: 16 | V27: 9 | W27: 40 | X27: 14 | Y27: 17 | Z27: 138 | AA27: 209 | AB27: 26 | AC27: 56 | AD27: 244.31 | AE27: 3 | AF27: 11220 | AG27: 15004.19 | AH27: No | AI27: No
A28: PI-2024-027 | B28: Keisha Wilson | C28: Motor Vehicle Accident | D28: Daniel Kowalski | E28: State Farm | F28: Closed | G28: 7. Closed | H28: 36683.46 | I28: 15000 | J28: 0.33 | K28: 11682.58 | L28: 5250 | M28: 45456 | N28: 45670 | O28: 45685 | P28: 45702 | Q28: 45712 | R28: 45723 | S28: 45760 | T28: 214 | U28: 15 | V28: 17 | W28: 10 | X28: 11 | Y28: 37 | Z28: 246 | AA28: 304 | AB28: 54 | AC28: 25 | AD28: 6432.58 | AE28: 55.1 | AF28: 4950 | AG28: 4800 | AH28: No | AI28: No
A29: PI-2024-028 | B29: Jennifer Martinez | C29: Motor Vehicle Accident | D29: Marcus Bell | E29: Allstate | F29: Closed | G29: 7. Closed | H29: 13463.18 | I29: 14750 | J29: 0.33 | K29: 4487.79 | L29: 3762.15 | M29: 45457 | N29: 45656 | O29: 45667 | P29: 45679 | Q29: 45713 | R29: 45728 | S29: 45771 | T29: 199 | U29: 11 | V29: 12 | W29: 34 | X29: 15 | Y29: 43 | Z29: 222 | AA29: 314 | AB29: 55 | AC29: 45 | AD29: 725.64 | AE29: 16.2 | AF29: 4867.5 | AG29: 6120.35 | AH29: No | AI29: No
A30: PI-2024-029 | B30: Jennifer Johnson | C30: Slip & Fall | D30: Priya Nair | E30: Allstate | F30: Closed | G30: 7. Closed | H30: 54278.7 | I30: 60250 | J30: 0.33 | K30: 11840.25 | L30: 9626.71 | M30: 45458 | N30: 45537 | O30: 45551 | P30: 45564 | Q30: 45640 | R30: 45659 | S30: 45674 | T30: 79 | U30: 14 | V30: 13 | W30: 76 | X30: 19 | Y30: 15 | Z30: 106 | AA30: 216 | AB30: 28 | AC30: 90 | AD30: 2213.54 | AE30: 18.7 | AF30: 19882.5 | AG30: 30740.79 | AH30: Yes | AI30: No | AJ30: Adjuster Offer
A31: PI-2024-030 | B31: Marcus Gonzalez | C31: Slip & Fall | D31: Priya Nair | E31: Liberty Mutual | F31: Closed | G31: 7. Closed | H31: 13005.67 | I31: 26000 | J31: 0.4 | K31: 4383.75 | L31: 3155.73 | M31: 45459 | N31: 45492 | O31: 45547 | P31: 45554 | Q31: 45595 | R31: 46015 | S31: 46039 | T31: 33 | U31: 55 | V31: 7 | W31: 41 | X31: 420 | Y31: 24 | Z31: 95 | AA31: 580 | AB31: 31 | AC31: 96 | AD31: 1228.02 | AE31: 28 | AF31: 10400 | AG31: 12444.27 | AH31: Yes | AI31: No | AJ31: Records/Bills
A32: PI-2024-031 | B32: Andre Gonzalez | C32: Motor Vehicle Accident | D32: Priya Nair | E32: Progressive | F32: Closed | G32: 7. Closed | H32: 14408.91 | I32: 22250 | J32: 0.33 | K32: 8268.99 | L32: 2400.52 | M32: 45462 | N32: 45631 | O32: 45681 | P32: 45692 | Q32: 45746 | R32: 45770 | S32: 45810 | T32: 169 | U32: 50 | V32: 11 | W32: 54 | X32: 24 | Y32: 40 | Z32: 230 | AA32: 348 | AB32: 51 | AC32: 104 | AD32: 5868.47 | AE32: 71 | AF32: 7342.5 | AG32: 12506.98 | AH32: Yes | AI32: No | AJ32: Records + Adjuster
A33: PI-2024-032 | B33: Monica Clark | C33: Slip & Fall | D33: Alicia Reyes | E33: Allstate | F33: Closed | G33: 7. Closed | H33: 16632.04 | I33: 32750 | J33: 0.33 | K33: 4757.78 | L33: 2362.57 | M33: 45466 | N33: 45652 | O33: 45665 | P33: 45680 | Q33: 45718 | R33: 45733 | S33: 45759 | T33: 186 | U33: 13 | V33: 15 | W33: 38 | X33: 15 | Y33: 26 | Z33: 214 | AA33: 293 | AB33: 41 | AC33: 51 | AD33: 2395.21 | AE33: 50.3 | AF33: 10807.5 | AG33: 19579.93 | AH33: No | AI33: No
A34: PI-2024-033 | B34: Stephanie Rodriguez | C34: Motor Vehicle Accident | D34: Daniel Kowalski | E34: Liberty Mutual | F34: Closed | G34: 7. Closed | H34: 39447.72 | I34: 73500 | J34: 0.33 | K34: 4671.1 | L34: 2518.15 | M34: 45469 | N34: 45639 | O34: 45660 | P34: 45676 | Q34: 45712 | R34: 45748 | S34: 45794 | T34: 170 | U34: 21 | V34: 16 | W34: 36 | X34: 36 | Y34: 46 | Z34: 207 | AA34: 325 | AB34: 62 | AC34: 57 | AD34: 2152.95 | AE34: 46.1 | AF34: 24255 | AG34: 46726.85 | AH34: No | AI34: No
A35: PI-2024-034 | B35: Tiffany Ramirez | C35: Pedestrian | D35: Daniel Kowalski | E35: State Farm | F35: Closed | G35: 7. Closed | H35: 35131.01 | I35: 15000 | J35: 0.4 | K35: 0 | L35: 0 | M35: 45470 | N35: 45658 | O35: 45669 | P35: 45678 | Q35: 45722 | R35: 46101 | S35: 46130 | T35: 188 | U35: 11 | V35: 9 | W35: 44 | X35: 379 | Y35: 29 | Z35: 208 | AA35: 660 | AB35: 38 | AC35: 55 | AD35: 0 | AF35: 6000 | AG35: 9000 | AH35: No | AI35: No
A36: PI-2024-035 | B36: Robert Rodriguez | C36: Dog Bite | D36: Jennifer Ortiz | E36: State Farm | F36: Closed | G36: 7. Closed | H36: 6654.64 | I36: 9250 | J36: 0.33 | K36: 1833.06 | L36: 561.15 | M36: 45475 | N36: 45563 | O36: 45591 | P36: 45601 | Q36: 45695 | R36: 45729 | S36: 45756 | T36: 88 | U36: 28 | V36: 10 | W36: 94 | X36: 34 | Y36: 27 | Z36: 126 | AA36: 281 | AB36: 37 | AC36: 122 | AD36: 1271.91 | AE36: 69.4 | AF36: 3052.5 | AG36: 5636.35 | AH36: Yes | AI36: No | AJ36: Adjuster Offer
A37: PI-2024-036 | B37: Ashley Jackson | C37: Motor Vehicle Accident | D37: Alicia Reyes | E37: Allstate | F37: Closed | G37: 7. Closed | H37: 35068.13 | I37: 50000 | J37: 0.33 | K37: 15000 | L37: 14387.88 | M37: 45476 | N37: 45758 | O37: 45766 | P37: 45772 | Q37: 45799 | R37: 45816 | S37: 45836 | T37: 282 | U37: 8 | V37: 6 | W37: 27 | X37: 17 | Y37: 20 | Z37: 296 | AA37: 360 | AB37: 26 | AC37: 35 | AD37: 612.12 | AE37: 4.1 | AF37: 16500 | AG37: 19112.12 | AH37: No | AI37: No
A38: PI-2024-037 | B38: Lauren Clark | C38: Motor Vehicle Accident | D38: Daniel Kowalski | E38: Progressive | F38: Closed | G38: 7. Closed | H38: 9431.25 | I38: 22500 | J38: 0.33 | K38: 2132.7 | L38: 627.45 | M38: 45481 | N38: 45679 | O38: 45744 | P38: 45756 | Q38: 45796 | R38: 45809 | S38: 45850 | T38: 198 | U38: 65 | V38: 12 | W38: 40 | X38: 13 | Y38: 41 | Z38: 275 | AA38: 369 | AB38: 53 | AC38: 105 | AD38: 1505.25 | AE38: 70.6 | AF38: 7425 | AG38: 14447.55 | AH38: Yes | AI38: No | AJ38: Records/Bills
A39: PI-2024-038 | B39: Jose Taylor | C39: Dog Bite | D39: Daniel Kowalski | E39: State Farm | F39: Closed | G39: 7. Closed | H39: 33182.07 | I39: 70750 | J39: 0.4 | K39: 8175.04 | L39: 5646.58 | M39: 45482 | N39: 45566 | O39: 45603 | P39: 45617 | Q39: 45632 | R39: 45889 | S39: 45931 | T39: 84 | U39: 37 | V39: 14 | W39: 15 | X39: 257 | Y39: 42 | Z39: 135 | AA39: 449 | AB39: 56 | AC39: 52 | AD39: 2528.46 | AE39: 30.9 | AF39: 28300 | AG39: 36803.42 | AH39: No | AI39: No
A40: PI-2024-039 | B40: Patricia Lewis | C40: Pedestrian | D40: Jennifer Ortiz | E40: State Farm | F40: Closed | G40: 7. Closed | H40: 33096.13 | I40: 12000 | J40: 0.33 | K40: 6958.75 | L40: 4200 | M40: 45486 | N40: 45634 | O40: 45662 | P40: 45680 | Q40: 45725 | R40: 45794 | S40: 45820 | T40: 148 | U40: 28 | V40: 18 | W40: 45 | X40: 69 | Y40: 26 | Z40: 194 | AA40: 334 | AB40: 44 | AC40: 73 | AD40: 2758.75 | AE40: 39.6 | AF40: 3960 | AG40: 3840 | AH40: No | AI40: No
...
